Workbook

Sheet Parameters
A1: Parameter | B1: Value | F1: Country | G1: Fixed_Effect | I1: Country | J1: EI_g_per_km
A2: Global Intercept | B2: 7.5947721 | F2: Afghanistan | G2: 0 | I2: Afghanistan | J2: 221.2
A3: Threshold S/M | B3: 88335.2 | F3: Algeria | G3: 0.93843223 | I3: Algeria | J3: 270.4
A4: Threshold M/L | B4: 329479.8 | F4: Angola | G4: 0.90252841 | I4: Angola | J4: 309.7
F5: Argentina | G5: 2.3228855 | I5: Argentina | J5: 270
A6: Size_Category | B6: Intercept_Dev | C6: Slope_Pop | D6: Slope_Density | F6: Australia | G6: 2.4834983 | I6: Australia | J6: 326.9
A7: Small | B7: -3.163533 | C7: 1.5830338 | D7: -0.6052845 | F7: Azerbaijan | G7: 1.8806423 | I7: Azerbaijan | J7: 275.8
A8: Medium | B8: -0.52957097 | C8: 1.2825406 | D8: -0.51243736 | F8: Bangladesh | G8: -1.175909 | I8: Bangladesh | J8: 109.7
A9: Large | B9: 0 | C9: 1.0359737 | D9: -0.20649952 | F9: Belarus | G9: 1.3332418 | I9: Belarus | J9: 257.8
F10: Belgium | G10: 2.3647815 | I10: Belgium | J10: 193
F11: Benin | G11: 1.3694721 | I11: Benin | J11: 229.7
F12: Bolivia | G12: 2.1374391 | I12: Bolivia | J12: 363.8
F13: Brazil | G13: 2.3502127 | I13: Brazil | J13: 211.8
F14: Burkina Faso | G14: 1.5205862 | I14: Burkina Faso | J14: 120.6
F15: Cameroon | G15: 1.3259195 | I15: Cameroon | J15: 276.9
F16: Canada | G16: 2.4527791 | I16: Canada | J16: 283.5
F17: Chad | G17: 0.61767194 | I17: Chad | J17: 336
F18: Chile | G18: 2.3369593 | I18: Chile | J18: 259.1
F19: China | G19: 1.1635803 | I19: China | J19: 254.9
F20: Colombia | G20: 1.9448954 | I20: Colombia | J20: 168.9
F21: Cuba | G21: 1.2907136 | I21: Cuba | J21: 215.2
... F100: Zimbabwe | G100: 1.6735476 | I100: Zimbabwe | J100: 309.7
I102: Global Default EI | J102: 226.2

Sheet City_EI
A1: City_Country_Key | B1: EI_g_per_km
A2: Rosarito|México | B2: 250.6
A3: Victoria|Canada | B3: 282.8
A4: Malacatán|Guatemala | B4: 223.5
A5: Ahuachapan|El Salvador | B5: 227.8
A6: Santa Rosa|Honduras | B6: 195.6
A7: Chinandega|Nicaragua | B7: 240.4
A8: Talara|Peru | B8: 174.1
A9: Salinas [Santa Elena]|Ecuador | B9: 231
A10: San Andrés|Colombia | B10: 175.4
A11: Pinar del Rio|Cuba | B11: 216.4
A12: Cruzeiro do Sul|Brazil | B12: 218.5
A13: Jérémie|Haiti | B13: 186.7
... A10271: Pingtan|China | B10271: 257.6

Sheet VKT Prediction Tool
A1: City | B1: Country | C1: Population | D1: Area_km2 | E1: Size_Category | F1: ln_Population | G1: ln_Density | H1: Country_FE | I1: Predicted_ln_VKT | J1: Predicted_VKT | K1: % EV | L1: ICE_VKT | M1: ICE_ VKT_Per_Capita | N1: EI_Source | O1: Emission_Intensity_g_per_km | P1: Total_CO2e_tonnes | Q1: Total_CO2e_tonnes_Per_Capita
A2: Example City | B2: United States | C2: 500000 | D2: 300 | E2: =IF(C2="","",IF(C2<Parameters!$B$3,"Small",IF(C2<Parameters!$B$4,"Medium","Large"))) -> Large | F2: =IF(AND(ISNUMBER(C2),C2>0),LN(C2),"") -> 13.122363 | G2: =IF(AND(ISNUMBER(C2),C2>0,ISNUMBER(D2),D2>0),LN(C2/D2),"") -> 7.4185809 | H2: =IF(B2="","",IFERROR(VLOOKUP(B2,Parameters!$F$2:$G$200,2,FALSE),0)) -> 2.7168448 | I2: =IF(OR(E2="",F2="",G2=""),"", Parameters!$B$2 + H2 + VLOOKUP(E2,Parameters!$A$7:$D$9,2,FALSE) + F2 * VLOOKUP(E2,Parameters!$A$7:$D$9,3,FALSE) + G2 * VLOOKUP(E2,Parameters!$A$7:$D$9,4,FALSE)) -> 22.374107 | J2: =IF(I2="","",EXP(I2)) -> 5.2113621e+09 | K2: 0 | L2: =J2-(J2*(K2/100)) -> 5.2113621e+09 | M2: =IF(OR(L2="",C2=0),"",L2/C2) -> 10422.724 | N2: =IF(A2="","",IF(ISNUMBER(MATCH(A2&"|"&B2,City_EI!$A$2:$B$10271,0)),"City",IF(ISNUMBER(MATCH(B2,Parameters!$I$2:$I$100,0)),"Country","Default"))) -> Country | O2: =IF(A2="","",IFERROR(VLOOKUP(A2&"|"&B2,City_EI!$A$2:$B$10271,2,FALSE),IFERROR(VLOOKUP(B2,Parameters!$I$2:$J$100,2,FALSE),226.2))) -> 331 | P2: =IF(OR(L2="",O2=""),"",L2*O2/1000000) -> 1724960.9 | Q2: =IF(OR(M2="",O2=""),"",M2*O2/1000000) -> 3.4499217
E3: =IF(C3="","",IF(C3<Parameters!$B$3,"Small",IF(C3<Parameters!$B$4,"Medium","Large"))) | F3: =IF(AND(ISNUMBER(C3),C3>0),LN(C3),"") | G3: =IF(AND(ISNUMBER(C3),C3>0,ISNUMBER(D3),D3>0),LN(C3/D3),"") | H3: =IF(B3="","",IFERROR(VLOOKUP(B3,Parameters!$F$2:$G$200,2,FALSE),0)) | I3: =IF(OR(E3="",F3="",G3=""),"", Parameters!$B$2 + H3 + VLOOKUP(E3,Parameters!$A$7:$D$9,2,FALSE) + F3 * VLOOKUP(E3,Parameters!$A$7:$D$9,3,FALSE) + G3 * VLOOKUP(E3,Parameters!$A$7:$D$9,4,FALSE)) | J3: =IF(I3="","",EXP(I3)) | M3: =IF(OR(J3="",C3=0),"",J3/C3) | N3: =IF(A3="","",IF(ISNUMBER(MATCH(A3&"|"&B3,City_EI!$A$2:$B$10271,0)),"City",IF(ISNUMBER(MATCH(B3,Parameters!$I$2:$I$100,0)),"Country","Default"))) | O3: =IF(A3="","",IFERROR(VLOOKUP(A3&"|"&B3,City_EI!$A$2:$B$10271,2,FALSE),IFERROR(VLOOKUP(B3,Parameters!$I$2:$J$100,2,FALSE),226.2))) | P3: =IF(OR(J3="",O3=""),"",J3*O3/1000000)
E4: =IF(C4="","",IF(C4<Parameters!$B$3,"Small",IF(C4<Parameters!$B$4,"Medium","Large"))) | F4: =IF(AND(ISNUMBER(C4),C4>0),LN(C4),"") | G4: =IF(AND(ISNUMBER(C4),C4>0,ISNUMBER(D4),D4>0),LN(C4/D4),"") | H4: =IF(B4="","",IFERROR(VLOOKUP(B4,Parameters!$F$2:$G$200,2,FALSE),0)) | I4: =IF(OR(E4="",F4="",G4=""),"", Parameters!$B$2 + H4 + VLOOKUP(E4,Parameters!$A$7:$D$9,2,FALSE) + F4 * VLOOKUP(E4,Parameters!$A$7:$D$9,3,FALSE) + G4 * VLOOKUP(E4,Parameters!$A$7:$D$9,4,FALSE)) | J4: =IF(I4="","",EXP(I4)) | M4: =IF(OR(J4="",C4=0),"",J4/C4) | N4: =IF(A4="","",IF(ISNUMBER(MATCH(A4&"|"&B4,City_EI!$A$2:$B$10271,0)),"City",IF(ISNUMBER(MATCH(B4,Parameters!$I$2:$I$100,0)),"Country","Default"))) | O4: =IF(A4="","",IFERROR(VLOOKUP(A4&"|"&B4,City_EI!$A$2:$B$10271,2,FALSE),IFERROR(VLOOKUP(B4,Parameters!$I$2:$J$100,2,FALSE),226.2))) | P4: =IF(OR(J4="",O4=""),"",J4*O4/1000000)
E5: =IF(C5="","",IF(C5<Parameters!$B$3,"Small",IF(C5<Parameters!$B$4,"Medium","Large"))) | F5: =IF(AND(ISNUMBER(C5),C5>0),LN(C5),"") | G5: =IF(AND(ISNUMBER(C5),C5>0,ISNUMBER(D5),D5>0),LN(C5/D5),"") | H5: =IF(B5="","",IFERROR(VLOOKUP(B5,Parameters!$F$2:$G$200,2,FALSE),0)) | I5: =IF(OR(E5="",F5="",G5=""),"", Parameters!$B$2 + H5 + VLOOKUP(E5,Parameters!$A$7:$D$9,2,FALSE) + F5 * VLOOKUP(E5,Parameters!$A$7:$D$9,3,FALSE) + G5 * VLOOKUP(E5,Parameters!$A$7:$D$9,4,FALSE)) | J5: =IF(I5="","",EXP(I5)) | M5: =IF(OR(J5="",C5=0),"",J5/C5) | N5: =IF(A5="","",IF(ISNUMBER(MATCH(A5&"|"&B5,City_EI!$A$2:$B$10271,0)),"City",IF(ISNUMBER(MATCH(B5,Parameters!$I$2:$I$100,0)),"Country","Default"))) | O5: =IF(A5="","",IFERROR(VLOOKUP(A5&"|"&B5,City_EI!$A$2:$B$10271,2,FALSE),IFERROR(VLOOKUP(B5,Parameters!$I$2:$J$100,2,FALSE),226.2))) | P5: =IF(OR(J5="",O5=""),"",J5*O5/1000000)
E6: =IF(C6="","",IF(C6<Parameters!$B$3,"Small",IF(C6<Parameters!$B$4,"Medium","Large"))) | F6: =IF(AND(ISNUMBER(C6),C6>0),LN(C6),"") | G6: =IF(AND(ISNUMBER(C6),C6>0,ISNUMBER(D6),D6>0),LN(C6/D6),"") | H6: =IF(B6="","",IFERROR(VLOOKUP(B6,Parameters!$F$2:$G$200,2,FALSE),0)) | I6: =IF(OR(E6="",F6="",G6=""),"", Parameters!$B$2 + H6 + VLOOKUP(E6,Parameters!$A$7:$D$9,2,FALSE) + F6 * VLOOKUP(E6,Parameters!$A$7:$D$9,3,FALSE) + G6 * VLOOKUP(E6,Parameters!$A$7:$D$9,4,FALSE)) | J6: =IF(I6="","",EXP(I6)) | M6: =IF(OR(J6="",C6=0),"",J6/C6) | N6: =IF(A6="","",IF(ISNUMBER(MATCH(A6&"|"&B6,City_EI!$A$2:$B$10271,0)),"City",IF(ISNUMBER(MATCH(B6,Parameters!$I$2:$I$100,0)),"Country","Default"))) | O6: =IF(A6="","",IFERROR(VLOOKUP(A6&"|"&B6,City_EI!$A$2:$B$10271,2,FALSE),IFERROR(VLOOKUP(B6,Parameters!$I$2:$J$100,2,FALSE),226.2))) | P6: =IF(OR(J6="",O6=""),"",J6*O6/1000000)
E7: =IF(C7="","",IF(C7<Parameters!$B$3,"Small",IF(C7<Parameters!$B$4,"Medium","Large"))) | F7: =IF(AND(ISNUMBER(C7),C7>0),LN(C7),"") | G7: =IF(AND(ISNUMBER(C7),C7>0,ISNUMBER(D7),D7>0),LN(C7/D7),"") | H7: =IF(B7="","",IFERROR(VLOOKUP(B7,Parameters!$F$2:$G$200,2,FALSE),0)) | I7: =IF(OR(E7="",F7="",G7=""),"", Parameters!$B$2 + H7 + VLOOKUP(E7,Parameters!$A$7:$D$9,2,FALSE) + F7 * VLOOKUP(E7,Parameters!$A$7:$D$9,3,FALSE) + G7 * VLOOKUP(E7,Parameters!$A$7:$D$9,4,FALSE)) | J7: =IF(I7="","",EXP(I7)) | M7: =IF(OR(J7="",C7=0),"",J7/C7) | N7: =IF(A7="","",IF(ISNUMBER(MATCH(A7&"|"&B7,City_EI!$A$2:$B$10271,0)),"City",IF(ISNUMBER(MATCH(B7,Parameters!$I$2:$I$100,0)),"Country","Default"))) | O7: =IF(A7="","",IFERROR(VLOOKUP(A7&"|"&B7,City_EI!$A$2:$B$10271,2,FALSE),IFERROR(VLOOKUP(B7,Parameters!$I$2:$J$100,2,FALSE),226.2))) | P7: =IF(OR(J7="",O7=""),"",J7*O7/1000000)
E8: =IF(C8="","",IF(C8<Parameters!$B$3,"Small",IF(C8<Parameters!$B$4,"Medium","Large"))) | F8: =IF(AND(ISNUMBER(C8),C8>0),LN(C8),"") | G8: =IF(AND(ISNUMBER(C8),C8>0,ISNUMBER(D8),D8>0),LN(C8/D8),"") | H8: =IF(B8="","",IFERROR(VLOOKUP(B8,Parameters!$F$2:$G$200,2,FALSE),0)) | I8: =IF(OR(E8="",F8="",G8=""),"", Parameters!$B$2 + H8 + VLOOKUP(E8,Parameters!$A$7:$D$9,2,FALSE) + F8 * VLOOKUP(E8,Parameters!$A$7:$D$9,3,FALSE) + G8 * VLOOKUP(E8,Parameters!$A$7:$D$9,4,FALSE)) | J8: =IF(I8="","",EXP(I8)) | M8: =IF(OR(J8="",C8=0),"",J8/C8) | N8: =IF(A8="","",IF(ISNUMBER(MATCH(A8&"|"&B8,City_EI!$A$2:$B$10271,0)),"City",IF(ISNUMBER(MATCH(B8,Parameters!$I$2:$I$100,0)),"Country","Default"))) | O8: =IF(A8="","",IFERROR(VLOOKUP(A8&"|"&B8,City_EI!$A$2:$B$10271,2,FALSE),IFERROR(VLOOKUP(B8,Parameters!$I$2:$J$100,2,FALSE),226.2))) | P8: =IF(OR(J8="",O8=""),"",J8*O8/1000000)
E9: =IF(C9="","",IF(C9<Parameters!$B$3,"Small",IF(C9<Parameters!$B$4,"Medium","Large"))) | F9: =IF(AND(ISNUMBER(C9),C9>0),LN(C9),"") | G9: =IF(AND(ISNUMBER(C9),C9>0,ISNUMBER(D9),D9>0),LN(C9/D9),"") | H9: =IF(B9="","",IFERROR(VLOOKUP(B9,Parameters!$F$2:$G$200,2,FALSE),0)) | I9: =IF(OR(E9="",F9="",G9=""),"", Parameters!$B$2 + H9 + VLOOKUP(E9,Parameters!$A$7:$D$9,2,FALSE) + F9 * VLOOKUP(E9,Parameters!$A$7:$D$9,3,FALSE) + G9 * VLOOKUP(E9,Parameters!$A$7:$D$9,4,FALSE)) | J9: =IF(I9="","",EXP(I9)) | M9: =IF(OR(J9="",C9=0),"",J9/C9) | N9: =IF(A9="","",IF(ISNUMBER(MATCH(A9&"|"&B9,City_EI!$A$2:$B$10271,0)),"City",IF(ISNUMBER(MATCH(B9,Parameters!$I$2:$I$100,0)),"Country","Default"))) | O9: =IF(A9="","",IFERROR(VLOOKUP(A9&"|"&B9,City_EI!$A$2:$B$10271,2,FALSE),IFERROR(VLOOKUP(B9,Parameters!$I$2:$J$100,2,FALSE),226.2))) | P9: =IF(OR(J9="",O9=""),"",J9*O9/1000000)
E10: =IF(C10="","",IF(C10<Parameters!$B$3,"Small",IF(C10<Parameters!$B$4,"Medium","Large"))) | F10: =IF(AND(ISNUMBER(C10),C10>0),LN(C10),"") | G10: =IF(AND(ISNUMBER(C10),C10>0,ISNUMBER(D10),D10>0),LN(C10/D10),"") | H10: =IF(B10="","",IFERROR(VLOOKUP(B10,Parameters!$F$2:$G$200,2,FALSE),0)) | I10: =IF(OR(E10="",F10="",G10=""),"", Parameters!$B$2 + H10 + VLOOKUP(E10,Parameters!$A$7:$D$9,2,FALSE) + F10 * VLOOKUP(E10,Parameters!$A$7:$D$9,3,FALSE) + G10 * VLOOKUP(E10,Parameters!$A$7:$D$9,4,FALSE)) | J10: =IF(I10="","",EXP(I10)) | M10: =IF(OR(J10="",C10=0),"",J10/C10) | N10: =IF(A10="","",IF(ISNUMBER(MATCH(A10&"|"&B10,City_EI!$A$2:$B$10271,0)),"City",IF(ISNUMBER(MATCH(B10,Parameters!$I$2:$I$100,0)),"Country","Default"))) | O10: =IF(A10="","",IFERROR(VLOOKUP(A10&"|"&B10,City_EI!$A$2:$B$10271,2,FALSE),IFERROR(VLOOKUP(B10,Parameters!$I$2:$J$100,2,FALSE),226.2))) | P10: =IF(OR(J10="",O10=""),"",J10*O10/1000000)
E11: =IF(C11="","",IF(C11<Parameters!$B$3,"Small",IF(C11<Parameters!$B$4,"Medium","Large"))) | F11: =IF(AND(ISNUMBER(C11),C11>0),LN(C11),"") | G11: =IF(AND(ISNUMBER(C11),C11>0,ISNUMBER(D11),D11>0),LN(C11/D11),"") | H11: =IF(B11="","",IFERROR(VLOOKUP(B11,Parameters!$F$2:$G$200,2,FALSE),0)) | I11: =IF(OR(E11="",F11="",G11=""),"", Parameters!$B$2 + H11 + VLOOKUP(E11,Parameters!$A$7:$D$9,2,FALSE) + F11 * VLOOKUP(E11,Parameters!$A$7:$D$9,3,FALSE) + G11 * VLOOKUP(E11,Parameters!$A$7:$D$9,4,FALSE)) | J11: =IF(I11="","",EXP(I11)) | M11: =IF(OR(J11="",C11=0),"",J11/C11) | N11: =IF(A11="","",IF(ISNUMBER(MATCH(A11&"|"&B11,City_EI!$A$2:$B$10271,0)),"City",IF(ISNUMBER(MATCH(B11,Parameters!$I$2:$I$100,0)),"Country","Default"))) | O11: =IF(A11="","",IFERROR(VLOOKUP(A11&"|"&B11,City_EI!$A$2:$B$10271,2,FALSE),IFERROR(VLOOKUP(B11,Parameters!$I$2:$J$100,2,FALSE),226.2))) | P11: =IF(OR(J11="",O11=""),"",J11*O11/1000000)
E12: =IF(C12="","",IF(C12<Parameters!$B$3,"Small",IF(C12<Parameters!$B$4,"Medium","Large"))) | F12: =IF(AND(ISNUMBER(C12),C12>0),LN(C12),"") | G12: =IF(AND(ISNUMBER(C12),C12>0,ISNUMBER(D12),D12>0),LN(C12/D12),"") | H12: =IF(B12="","",IFERROR(VLOOKUP(B12,Parameters!$F$2:$G$200,2,FALSE),0)) | I12: =IF(OR(E12="",F12="",G12=""),"", Parameters!$B$2 + H12 + VLOOKUP(E12,Parameters!$A$7:$D$9,2,FALSE) + F12 * VLOOKUP(E12,Parameters!$A$7:$D$9,3,FALSE) + G12 * VLOOKUP(E12,Parameters!$A$7:$D$9,4,FALSE)) | J12: =IF(I12="","",EXP(I12)) | M12: =IF(OR(J12="",C12=0),"",J12/C12) | N12: =IF(A12="","",IF(ISNUMBER(MATCH(A12&"|"&B12,City_EI!$A$2:$B$10271,0)),"City",IF(ISNUMBER(MATCH(B12,Parameters!$I$2:$I$100,0)),"Country","Default"))) | O12: =IF(A12="","",IFERROR(VLOOKUP(A12&"|"&B12,City_EI!$A$2:$B$10271,2,FALSE),IFERROR(VLOOKUP(B12,Parameters!$I$2:$J$100,2,FALSE),226.2))) | P12: =IF(OR(J12="",O12=""),"",J12*O12/1000000)
E13: =IF(C13="","",IF(C13<Parameters!$B$3,"Small",IF(C13<Parameters!$B$4,"Medium","Large"))) | F13: =IF(AND(ISNUMBER(C13),C13>0),LN(C13),"") | G13: =IF(AND(ISNUMBER(C13),C13>0,ISNUMBER(D13),D13>0),LN(C13/D13),"") | H13: =IF(B13="","",IFERROR(VLOOKUP(B13,Parameters!$F$2:$G$200,2,FALSE),0)) | I13: =IF(OR(E13="",F13="",G13=""),"", Parameters!$B$2 + H13 + VLOOKUP(E13,Parameters!$A$7:$D$9,2,FALSE) + F13 * VLOOKUP(E13,Parameters!$A$7:$D$9,3,FALSE) + G13 * VLOOKUP(E13,Parameters!$A$7:$D$9,4,FALSE)) | J13: =IF(I13="","",EXP(I13)) | M13: =IF(OR(J13="",C13=0),"",J13/C13) | N13: =IF(A13="","",IF(ISNUMBER(MATCH(A13&"|"&B13,City_EI!$A$2:$B$10271,0)),"City",IF(ISNUMBER(MATCH(B13,Parameters!$I$2:$I$100,0)),"Country","Default"))) | O13: =IF(A13="","",IFERROR(VLOOKUP(A13&"|"&B13,City_EI!$A$2:$B$10271,2,FALSE),IFERROR(VLOOKUP(B13,Parameters!$I$2:$J$100,2,FALSE),226.2))) | P13: =IF(OR(J13="",O13=""),"",J13*O13/1000000)
E14: =IF(C14="","",IF(C14<Parameters!$B$3,"Small",IF(C14<Parameters!$B$4,"Medium","Large"))) | F14: =IF(AND(ISNUMBER(C14),C14>0),LN(C14),"") | G14: =IF(AND(ISNUMBER(C14),C14>0,ISNUMBER(D14),D14>0),LN(C14/D14),"") | H14: =IF(B14="","",IFERROR(VLOOKUP(B14,Parameters!$F$2:$G$200,2,FALSE),0)) | I14: =IF(OR(E14="",F14="",G14=""),"", Parameters!$B$2 + H14 + VLOOKUP(E14,Parameters!$A$7:$D$9,2,FALSE) + F14 * VLOOKUP(E14,Parameters!$A$7:$D$9,3,FALSE) + G14 * VLOOKUP(E14,Parameters!$A$7:$D$9,4,FALSE)) | J14: =IF(I14="","",EXP(I14)) | M14: =IF(OR(J14="",C14=0),"",J14/C14) | N14: =IF(A14="","",IF(ISNUMBER(MATCH(A14&"|"&B14,City_EI!$A$2:$B$10271,0)),"City",IF(ISNUMBER(MATCH(B14,Parameters!$I$2:$I$100,0)),"Country","Default"))) | O14: =IF(A14="","",IFERROR(VLOOKUP(A14&"|"&B14,City_EI!$A$2:$B$10271,2,FALSE),IFERROR(VLOOKUP(B14,Parameters!$I$2:$J$100,2,FALSE),226.2))) | P14: =IF(OR(J14="",O14=""),"",J14*O14/1000000)
... E101: =IF(C101="","",IF(C101<Parameters!$B$3,"Small",IF(C101<Parameters!$B$4,"Medium","Large"))) | F101: =IF(AND(ISNUMBER(C101),C101>0),LN(C101),"") | G101: =IF(AND(ISNUMBER(C101),C101>0,ISNUMBER(D101),D101>0),LN(C101/D101),"") | H101: =IF(B101="","",IFERROR(VLOOKUP(B101,Parameters!$F$2:$G$200,2,FALSE),0)) | I101: =IF(OR(E101="",F101="",G101=""),"", Parameters!$B$2 + H101 + VLOOKUP(E101,Parameters!$A$7:$D$9,2,FALSE) + F101 * VLOOKUP(E101,Parameters!$A$7:$D$9,3,FALSE) + G101 * VLOOKUP(E101,Parameters!$A$7:$D$9,4,FALSE)) | J101: =IF(I101="","",EXP(I101)) | M101: =IF(OR(J101="",C101=0),"",J101/C101) | N101: =IF(A101="","",IF(ISNUMBER(MATCH(A101&"|"&B101,City_EI!$A$2:$B$10271,0)),"City",IF(ISNUMBER(MATCH(B101,Parameters!$I$2:$I$100,0)),"Country","Default"))) | O101: =IF(A101="","",IFERROR(VLOOKUP(A101&"|"&B101,City_EI!$A$2:$B$10271,2,FALSE),IFERROR(VLOOKUP(B101,Parameters!$I$2:$J$100,2,FALSE),226.2))) | P101: =IF(OR(J101="",O101=""),"",J101*O101/1000000)

Sheet City Country
A1: geometry_ref | B1: name | C1: country
A2: 1728 | B2: Zaranj | C2: Afghanistan
A3: 3029 | B3: Lashkar Gah | C3: Afghanistan
A4: 5287 | B4: Jalalabad | C4: Afghanistan
A5: 4760 | B5: Ghazni | C5: Afghanistan
A6: 5339 | B6: Trilyee Family | C6: Afghanistan
A7: 3259 | B7: Mazar i sharif | C7: Afghanistan
A8: 4352 | B8: Chaman | C8: Afghanistan
A9: 2382 | B9: Maymana | C9: Afghanistan
A10: 4079 | B10: Kunduz | C10: Afghanistan
A11: 3909 | B11: Kandahar | C11: Afghanistan
A12: 4725 | B12: Charikar | C12: Afghanistan
A13: 2655 | B13: Sheberghan | C13: Afghanistan
... A50: 1540 | B50: Obe | C50: Afghanistan
A51: 3147 | C51: Afghanistan
A52: 1125 | B52: Bandabad | C52: Afghanistan
A53: 3820 | B53: Pasab | C53: Afghanistan
A54: 3579 | B54: Deh Rawud | C54: Afghanistan
A55: 4614 | B55: Siyahgird | C55: Afghanistan
A56: 5204 | B56: Khand Khil | C56: Afghanistan
A57: 2783 | B57: Sayad | C57: Afghanistan
A58: 2455 | B58: Emam Saheb | C58: Afghanistan
A59: 3369 | B59: Mirzay | C59: Afghanistan
A60: 3682 | B60: Orlamish | C60: Afghanistan
A61: 482 | B61: Qarab?g | C61: Afghanistan
A62: 2719 | B62: Darzab | C62: Afghanistan
A63: 3995 | B63: Nao Deh | C63: Afghanistan
... A3455: 6386 | B3455: Al-Zawamel | C3455: Egypt
A3456: 6879 | C3456: Egypt
A3457: 5460 | B3457: ?????? | C3457: Egypt
A3458: 3902 | B3458: Al Hiatem | C3458: Egypt
A3459: 2365 | B3459: Kafr Al-Zaiyat | C3459: Egypt
A3460: 6850 | B3460: Al-Asafra | C3460: Egypt
A3461: 5252 | B3461: Al-Minya | C3461: Egypt
A3462: 7301 | B3462: Hijazah | C3462: Egypt
A3463: 2706 | B3463: Terenuthis | C3463: Egypt
A3464: 4192 | B3464: Tall al Bahnasa | C3464: Egypt
A3465: 4113 | B3465: Shimm al Basal al Bahari | C3465: Egypt
A3466: 2957 | B3466: Tala | C3466: Egypt
A3467: 3857 | B3467: Mit Afia | C3467: Egypt
...
